Workbook

Sheet Document Control
A2: Copyright © 2025 Foodics. All rights reserved.
A3: Anti Financial Crime - Risk Register | D3: Date: | E3: 45685
D4: Version: | E4: 1
D5: Classification: | E5: Internal
D6: Status | E6: Final
A7: Document Information
A9: Document Title | B9: Foodics - Anti Financial Crime - Risk Register | C9: No. of Sheets | D9: 4
A12: Document Developer
A14: Name | B14: Sohaib Aijaz
A17: Title | B17: Risk Specialist | C17: Department | D17: Risk Management Department
A20: Document Approval
A22: Foodics <<Insert Designation>> | C22: Date
A25: Foodics <<Insert Designation>> | C25: Date
A28: Document Version History
A29: Modification History | C29: Author | D29: Date | E29: Version
A30: Initial draft | C30: Risk Management Department | D30: 45685 | E30: 0.1
A32: Document Monitoring History
A34: Review Frequency | B34: Annually | C34: Responsibility | D34: <<Insert department>>
A37: Version | B37: Last Reviewed | C37: Next Review | D37: Reviewer | E37: Sign Off

Sheet Introductions
A2: Copyright © 2025 Foodics. All rights reserved.
A3: Anti Financial Crime - Risk Register
A4: Objective | B4: The objective of this document is to collate information on Foodics availability risks that could affect the continuous operation of critical systems and services.
A5: Instructions | B5: Please keep a note of the below instructions while filling the sheet:
B6: Sheet 1: This contains version control information.
B7: Current Sheet (Sheet 2): This contains general information about the document.
B8: Sheet 3: Availability Risk Register (instructions are provided in column).
B9: Sheet 4: Risk Matrix.
O19: Recruitment will be conducted based on approved and available positions to meet operational requirements | P19: Fill approved vacant positions based on business requirements | Q19: Q4 timeline
K21: Deployed automated transaction monitoring systems with predefined rules and generate alerts for anomalies. 1-Review and update monitoring rules and thresholds based on risk assessment (BRA/CRA) 2-Ensure full integration between core system and monitoring system (e.g., FOCAL) 3-Implement periodic tuning and validation of alerts to reduce false positives 4-Establish escalation and review procedures for alerts (including Compliance approval) 4-Conduct regular testing and quality assurance (sampling every 6 months)
K22: Conduct risk assessments on customers and flag PEPs as high-risk with enhanced monitoring. 1-Implemented automated PEP screening integrated with onboarding and monitoring systems 2-Ensure all identified PEPs are classified as high-risk and subject to EDD 3-Enforce mandatory senior management (CEO) approval before onboarding PEPs 4-Apply enhanced ongoing monitoring for PEP accounts and transactions 5-Conduct periodic reviews and updates of PEP status and related risk profiles
K23: BRA has been developed and finalized
K151: Assign Compliance responsibility to alert Marketing of any regulatory or policy changes requiring updates.
K153: Skills development occurs organically through on-the-job learning, peer collaboration, and ad-hoc exposure to new tools and industry practices. - Could include access to certified training and programs for the team (through HR) - Implement a routine team knowledge sharing hub about new marketing trends, channels and tools, industry case studies.. etc. This will ensure continuous development beyond daily operational tasks and support long-term capability maturity.
E173: Risk that business, operational, regulatory or customer requirements are incomplete, inaccurate, ambiguous or incorrectly translated into technical specifications during product development or enhancement. Inadequate stakeholder consultation, poorly documented requirements or uncontrolled changes may result in incorrect functionality, processing errors, missed regulatory requirements, production defects, rework, financial loss and customer impact.
K186: 1.⁠ ⁠Terminal-level transaction visibility. Every transaction records the terminal that originated it, so a device that has stopped processing is identifiable from platform data without relying on the merchant to report it. 2.⁠ ⁠Daily terminal-level reconciliation. Transactions are reconciled per terminal per day against payment service provider reports, so a terminal that is not reporting or is reporting incompletely is detectable through the reconciliation cycle. 3.⁠ ⁠Central terminal registry with lifecycle management. Terminals are registered against a merchant and branch with their status maintained centrally, so a failed device can be deactivated and a replacement registered against the same merchant and branch. 4.⁠ ⁠Independent approval and audit trail on terminal record changes, so device deactivations and replacements are authorised by a second person and fully traceable. 5.⁠ ⁠Per-terminal integration logging. Failures originating at a device are logged with the exact message exchange, allowing a connectivity failure to be distinguished from an application or platform failure during investigation.

Sheet Availability Risk Register
A2: Copyright © 2025 Foodics. All rights reserved.
A3: Enterprise - Risk Register
A4: Availability Risks
A5: Risk ID | B5: Risk Category | C5: Risk Name | D5: Owner | E5: Risk Description | F5: Likelihood | G5: Risk Impact | H5: Score | J5: Inherent Risk | K5: Existing Controls | L5: Control Effectiveness | M5: Residual risk | N5: ACTION OWNER | O5: Recommended Treatment | P5: Action Plan | Q5: Target completion date | R5: Control Effectiveness | S5: Risk after treatment | U5: Status | V5: Department Responses
A7: Serial number | C7: Define the risk | D7: Foodics Department responsible for managing the risk | E7: A detailed explanation of the risk with the potential impact | F7: The possibility that the risk could occur | G7: The impact on the department if that risk occurs | H7: L and I | J7: The likelihood and impact of a risk occurrence | K7: a | L7: Strength of the existing controls | M7: Residual risk after existing control | O7: The additional controls that are required to effectively mitigate risk | P7: clear list of steps that explain how you will apply the recommended treatment to reduce the risk. | Q7: Tentative date to complete the recommended treatment | R7: Control strength based on the existing controls and the additional identified controls | S7: Net risk that remain after considering control effectiveness and risk severity | T7: Your Task
A8: AFC-001 | B8: People | C8: Incorrect /fake documentation | D8: Anti Money Laundering | E8: Risk of an individual at the time of onboarding might provide incorrect personal information with malicious intentions, lead to fraudulent transactions. | F8: Likely | G8: Major | H8: =IF(F8='Risk Methedology Matrix'!B$26,5,IF(F8='Risk Methedology Matrix'!B$27,4,IF(F8='Risk Methedology Matrix'!B$28,3,IF(F8='Risk Methedology Matrix'!B$29,2,IF(F8='Risk Methedology Matrix'!B$30,1,0))))) -> 4 | I8: =IF(G8='Risk Methedology Matrix'!G$25,5,IF(G8='Risk Methedology Matrix'!F$25,4,IF(G8='Risk Methedology Matrix'!E$25,3,IF(G8='Risk Methedology Matrix'!D$25,2,IF(G8='Risk Methedology Matrix'!C$25,1,0))))) -> 4 | J8: =IF(OR(F8="",G8=""),"",IF(H8*I8>=20,"Very High",IF(AND(H8*I8<20,H8*I8>=11),"High",IF(AND(H8*I8<11,H8*I8>=6),"Medium",IF(AND(H8*I8<6,H8*I8>=3),"Low",IF(AND(H8*I8<3,H8*I8>=1),"Very Low","")))))) -> High | K8: Personal information including CR number, phone number and National ID are validated via third party servies like wathiq, yakeen and absher 2) Enhance data validation by ensuring customer information is verified through available third-party services during onboarding with clear checks before account activation 3-Define key fields to be verified (e.g., CR number, National ID, mobile number) 4-Perform validation through available third-party services (e.g., Wathiq, Yakeen, Absher) during onboarding 5-Ensure validation is completed before activating the customer account 6-Follow up on any incomplete or failed validation before proceeding. Keep basic records of validation results for reference | L8: Good | M8: =IF(OR(J8="",L8=""),"", IF(AND(J8="Very High",L8="Excellent"),"Low", IF(AND(J8="Very High",L8="Good"),"Medium", IF(AND(J8="Very High",L8="Fair"),"High", IF(AND(J8="Very High",L8="Poor"),"Very High", IF(AND(J8="Very High",L8="Unsatisfactory"),"Very High", IF(AND(J8="High",L8="Excellent"),"Very Low", IF(AND(J8="High",L8="Good"),"Low", IF(AND(J8="High",L8="Fair"),"Medium", IF(AND(J8="High",L8="Poor"),"High", IF(AND(J8="High",L8="Unsatisfactory"),"High", IF(AND(J8="Medium",L8="Excellent"),"Very Low", IF(AND(J8="Medium",L8="Good"),"Very Low", IF(AND(J8="Medium",L8="Fair"),"Low", IF(AND(J8="Medium",L8="Poor"),"Medium", IF(AND(J8="Medium",L8="Unsatisfactory"),"Medium", IF(AND(J8="Low",L8="Excellent"),"Very Low", IF(AND(J8="Low",L8="Good"),"Very Low", IF(AND(J8="Low",L8="Fair"),"Very Low", IF(AND(J8="Low",L8="Poor"),"Low", IF(AND(J8="Low",L8="Unsatisfactory"),"Low", IF(AND(J8="Very Low",L8="Excellent"),"Very Low", IF(AND(J8="Very Low",L8="Good"),"Very Low", IF(AND(J8="Very Low",L8="Fair"),"Very Low", IF(AND(J8="Very Low",L8="Poor"),"Very Low", IF(AND(J8="Very Low",L8="Unsatisfactory"),"Very Low","")))))))))))))))))))))))))) -> Low | S8: =IF(OR(L8="",R8=""),"",IF(AND(L8="Very High",R8="Excellent"),"Low",IF(AND(L8="Very High",R8="Good"),"Medium",IF(AND(L8="Very High",R8="Fair"),"High",IF(AND(L8="Very High",R8="Poor"),"Very High",IF(AND(L8="Very High",R8="Unsatisfactory"),"Very High",IF(AND(L8="High",R8="Excellent"),"Low",IF(AND(L8="High",R8="Good"),"Low",IF(AND(L8="High",R8="Fair"),"Medium",IF(AND(L8="High",R8="Poor"),"High",IF(AND(L8="High",R8="Unsatisfactory"),"High",IF(AND(L8="Medium",R8="Excellent"),"Low",IF(AND(L8="Medium",R8="Good"),"Low",IF(AND(L8="Medium",R8="Fair"),"Low",IF(AND(L8="Medium",R8="Poor"),"Medium",IF(AND(L8="Medium",R8="Unsatisfactory"),"Medium",IF(AND(L8="Low",R8="Excellent"),"Very Low",IF(AND(L8="Low",R8="Good"),"Low",IF(AND(L8="Low",R8="Fair"),"Low",IF(AND(L8="Low",R8="Poor"),"Low",IF(AND(L8="Low",R8="Unsatisfactory"),"Low",IF(AND(L8="Very Low",R8="Excellent"),"Very Low",IF(AND(L8="Very Low",R8="Good"),"Very Low",IF(AND(L8="Very Low",R8="Fair"),"Very Low",IF(AND(L8="Very Low",R8="Poor"),"Very Low",IF(AND(L8="Very Low",R8="Unsatisfactory"),"Very Low","Low")))))))))))))))))))))))))) | T8: (check Operation team
A9: AFC-002 | B9: Process | C9: Sanction Screening | D9: Anti Money Laundering | E9: Inadequate sanctions screening for clients and transactions | F9: Likely | G9: Minor | H9: =IF(F9='Risk Methedology Matrix'!B$26,5,IF(F9='Risk Methedology Matrix'!B$27,4,IF(F9='Risk Methedology Matrix'!B$28,3,IF(F9='Risk Methedology Matrix'!B$29,2,IF(F9='Risk Methedology Matrix'!B$30,1,0))))) -> 4 | I9: =IF(G9='Risk Methedology Matrix'!G$25,5,IF(G9='Risk Methedology Matrix'!F$25,4,IF(G9='Risk Methedology Matrix'!E$25,3,IF(G9='Risk Methedology Matrix'!D$25,2,IF(G9='Risk Methedology Matrix'!C$25,1,0))))) -> 2 | J9: =IF(OR(F9="",G9=""),"",IF(H9*I9>=20,"Very High",IF(AND(H9*I9<20,H9*I9>=11),"High",IF(AND(H9*I9<11,H9*I9>=6),"Medium",IF(AND(H9*I9<6,H9*I9>=3),"Low",IF(AND(H9*I9<3,H9*I9>=1),"Very Low","")))))) -> Medium | K9: Customer names are screened through FOCAL against the applicable sanctions lists during the onboarding process Screening records and results are retained as supporting evidence In addition, customer names are periodically re-screened to identify any subsequent sanctions matches or changes in their sanctions status. | L9: Fair | M9: =IF(OR(J9="",L9=""),"", IF(AND(J9="Very High",L9="Excellent"),"Low", IF(AND(J9="Very High",L9="Good"),"Medium", IF(AND(J9="Very High",L9="Fair"),"High", IF(AND(J9="Very High",L9="Poor"),"Very High", IF(AND(J9="Very High",L9="Unsatisfactory"),"Very High", IF(AND(J9="High",L9="Excellent"),"Very Low", IF(AND(J9="High",L9="Good"),"Low", IF(AND(J9="High",L9="Fair"),"Medium", IF(AND(J9="High",L9="Poor"),"High", IF(AND(J9="High",L9="Unsatisfactory"),"High", IF(AND(J9="Medium",L9="Excellent"),"Very Low", IF(AND(J9="Medium",L9="Good"),"Very Low", IF(AND(J9="Medium",L9="Fair"),"Low", IF(AND(J9="Medium",L9="Poor"),"Medium", IF(AND(J9="Medium",L9="Unsatisfactory"),"Medium", IF(AND(J9="Low",L9="Excellent"),"Very Low", IF(AND(J9="Low",L9="Good"),"Very Low", IF(AND(J9="Low",L9="Fair"),"Very Low", IF(AND(J9="Low",L9="Poor"),"Low", IF(AND(J9="Low",L9="Unsatisfactory"),"Low", IF(AND(J9="Very Low",L9="Excellent"),"Very Low", IF(AND(J9="Very Low",L9="Good"),"Very Low", IF(AND(J9="Very Low",L9="Fair"),"Very Low", IF(AND(J9="Very Low",L9="Poor"),"Very Low", IF(AND(J9="Very Low",L9="Unsatisfactory"),"Very Low","")))))))))))))))))))))))))) -> Low | S9: =IF(OR(L9="",R9=""),"",IF(AND(L9="Very High",R9="Excellent"),"Low",IF(AND(L9="Very High",R9="Good"),"Medium",IF(AND(L9="Very High",R9="Fair"),"High",IF(AND(L9="Very High",R9="Poor"),"Very High",IF(AND(L9="Very High",R9="Unsatisfactory"),"Very High",IF(AND(L9="High",R9="Excellent"),"Low",IF(AND(L9="High",R9="Good"),"Low",IF(AND(L9="High",R9="Fair"),"Medium",IF(AND(L9="High",R9="Poor"),"High",IF(AND(L9="High",R9="Unsatisfactory"),"High",IF(AND(L9="Medium",R9="Excellent"),"Low",IF(AND(L9="Medium",R9="Good"),"Low",IF(AND(L9="Medium",R9="Fair"),"Low",IF(AND(L9="Medium",R9="Poor"),"Medium",IF(AND(L9="Medium",R9="Unsatisfactory"),"Medium",IF(AND(L9="Low",R9="Excellent"),"Very Low",IF(AND(L9="Low",R9="Good"),"Low",IF(AND(L9="Low",R9="Fair"),"Low",IF(AND(L9="Low",R9="Poor"),"Low",IF(AND(L9="Low",R9="Unsatisfactory"),"Low",IF(AND(L9="Very Low",R9="Excellent"),"Very Low",IF(AND(L9="Very Low",R9="Good"),"Very Low",IF(AND(L9="Very Low",R9="Fair"),"Very Low",IF(AND(L9="Very Low",R9="Poor"),"Very Low",IF(AND(L9="Very Low",R9="Unsatisfactory"),"Very Low","Low")))))))))))))))))))))))))) | T9: - (Action plan to reduce the alerts on focal + time line + controls) Chatgpt
A10: AFC-003 | B10: Process | C10: Negligence of Customer complaints | D10: Anti Money Laundering | E10: Failure to respond to customer complaints about suspicious activity , leads to financial loss, | F10: Likely | G10: Critical | H10: =IF(F10='Risk Methedology Matrix'!B$26,5,IF(F10='Risk Methedology Matrix'!B$27,4,IF(F10='Risk Methedology Matrix'!B$28,3,IF(F10='Risk Methedology Matrix'!B$29,2,IF(F10='Risk Methedology Matrix'!B$30,1,0))))) -> 4 | I10: =IF(G10='Risk Methedology Matrix'!G$25,5,IF(G10='Risk Methedology Matrix'!F$25,4,IF(G10='Risk Methedology Matrix'!E$25,3,IF(G10='Risk Methedology Matrix'!D$25,2,IF(G10='Risk Methedology Matrix'!C$25,1,0))))) -> 5 | J10: =IF(OR(F10="",G10=""),"",IF(H10*I10>=20,"Very High",IF(AND(H10*I10<20,H10*I10>=11),"High",IF(AND(H10*I10<11,H10*I10>=6),"Medium",IF(AND(H10*I10<6,H10*I10>=3),"Low",IF(AND(H10*I10<3,H10*I10>=1),"Very Low","")))))) -> Very High | K10: AML teams notify PayOps, for any merchant with suspicious activities, and hold their settlements, where our role is to ask the merchant for the needed documents and invoices to help the compliance teams investigate further how legitimate the transaction is. Specially if its with a high amount. 1-Define criteria to identify complaints that may indicate suspicious activity 2-Require escalation of such complaints to the Compliance team 3-Perform manual review of related transactions through existing AML systems (e.g., FOCAL) 4-Document all escalations and investigation outcomes 5-Provide basic awareness to relevant teams on identifying suspicious complaints | L10: Good | M10: =IF(OR(J10="",L10=""),"", IF(AND(J10="Very High",L10="Excellent"),"Low", IF(AND(J10="Very High",L10="Good"),"Medium", IF(AND(J10="Very High",L10="Fair"),"High", IF(AND(J10="Very High",L10="Poor"),"Very High", IF(AND(J10="Very High",L10="Unsatisfactory"),"Very High", IF(AND(J10="High",L10="Excellent"),"Very Low", IF(AND(J10="High",L10="Good"),"Low", IF(AND(J10="High",L10="Fair"),"Medium", IF(AND(J10="High",L10="Poor"),"High", IF(AND(J10="High",L10="Unsatisfactory"),"High", IF(AND(J10="Medium",L10="Excellent"),"Very Low", IF(AND(J10="Medium",L10="Good"),"Very Low", IF(AND(J10="Medium",L10="Fair"),"Low", IF(AND(J10="Medium",L10="Poor"),"Medium", IF(AND(J10="Medium",L10="Unsatisfactory"),"Medium", IF(AND(J10="Low",L10="Excellent"),"Very Low", IF(AND(J10="Low",L10="Good"),"Very Low", IF(AND(J10="Low",L10="Fair"),"Very Low", IF(AND(J10="Low",L10="Poor"),"Low", IF(AND(J10="Low",L10="Unsatisfactory"),"Low", IF(AND(J10="Very Low",L10="Excellent"),"Very Low", IF(AND(J10="Very Low",L10="Good"),"Very Low", IF(AND(J10="Very Low",L10="Fair"),"Very Low", IF(AND(J10="Very Low",L10="Poor"),"Very Low", IF(AND(J10="Very Low",L10="Unsatisfactory"),"Very Low","")))))))))))))))))))))))))) -> Medium | S10: =IF(OR(L10="",R10=""),"",IF(AND(L10="Very High",R10="Excellent"),"Low",IF(AND(L10="Very High",R10="Good"),"Medium",IF(AND(L10="Very High",R10="Fair"),"High",IF(AND(L10="Very High",R10="Poor"),"Very High",IF(AND(L10="Very High",R10="Unsatisfactory"),"Very High",IF(AND(L10="High",R10="Excellent"),"Low",IF(AND(L10="High",R10="Good"),"Low",IF(AND(L10="High",R10="Fair"),"Medium",IF(AND(L10="High",R10="Poor"),"High",IF(AND(L10="High",R10="Unsatisfactory"),"High",IF(AND(L10="Medium",R10="Excellent"),"Low",IF(AND(L10="Medium",R10="Good"),"Low",IF(AND(L10="Medium",R10="Fair"),"Low",IF(AND(L10="Medium",R10="Poor"),"Medium",IF(AND(L10="Medium",R10="Unsatisfactory"),"Medium",IF(AND(L10="Low",R10="Excellent"),"Very Low",IF(AND(L10="Low",R10="Good"),"Low",IF(AND(L10="Low",R10="Fair"),"Low",IF(AND(L10="Low",R10="Poor"),"Low",IF(AND(L10="Low",R10="Unsatisfactory"),"Low",IF(AND(L10="Very Low",R10="Excellent"),"Very Low",IF(AND(L10="Very Low",R10="Good"),"Very Low",IF(AND(L10="Very Low",R10="Fair"),"Very Low",IF(AND(L10="Very Low",R10="Poor"),"Very Low",IF(AND(L10="Very Low",R10="Unsatisfactory"),"Very Low","Low")))))))))))))))))))))))))) | T10: (check Call center for the procedures the relates to fruad)
A11: AFC-004 | B11: People | C11: Not reporting suspicious transactions | D11: Anti Money Laundering | E11: Failure to inform the competent authorities in case of suspicion of valid reasons for fraudulent behavior by customers, lead to financial loss, reputational impact and legal prosecution. | F11: Likely | G11: Moderate | H11: =IF(F11='Risk Methedology Matrix'!B$26,5,IF(F11='Risk Methedology Matrix'!B$27,4,IF(F11='Risk Methedology Matrix'!B$28,3,IF(F11='Risk Methedology Matrix'!B$29,2,IF(F11='Risk Methedology Matrix'!B$30,1,0))))) -> 4 | I11: =IF(G11='Risk Methedology Matrix'!G$25,5,IF(G11='Risk Methedology Matrix'!F$25,4,IF(G11='Risk Methedology Matrix'!E$25,3,IF(G11='Risk Methedology Matrix'!D$25,2,IF(G11='Risk Methedology Matrix'!C$25,1,0))))) -> 3 | J11: =IF(OR(F11="",G11=""),"",IF(H11*I11>=20,"Very High",IF(AND(H11*I11<20,H11*I11>=11),"High",IF(AND(H11*I11<11,H11*I11>=6),"Medium",IF(AND(H11*I11<6,H11*I11>=3),"Low",IF(AND(H11*I11<3,H11*I11>=1),"Very Low","")))))) -> High | K11: In the event of encountering suspected cases of money laundering transactions on these accounts, staff of the Anti-Financial Crime Unit will examine the case and report to the head of the Anti-Financial Crime Unit who will decide to report the case to the Financial Investigations Unit (FIU) of the Ministry of Interior. Conducting Transaction Monitoring to detect unusual and suspicious activity. In case there are reasonable grounds to suspect that another person or entity engaging in Financial Crime: Escalating to the Financial Crime Unit by submitting unusual activity reports. Any employee should be able to escalate this report to the Financial Crime Unit in order that the unit can examine and take appropriate measures. Filing a Suspicious Activity Report (SAR) to the authorities (SAFIU) within 10 working days of validation. 1-Detect suspicious transactions through automated transaction monitoring systems. 2-Ensure all alerts are reviewed and investigated by the Compliance team. 3-Establish clear escalation procedures for potential suspicious cases 4-Define decision-making authority for filing Suspicious Activity Reports (SARs) 5-Ensure timely submission of SARs to SAFIU within regulatory timelines 6-Maintain proper documentation and audit trails for all investigations and reporting decisions | L11: Fair | M11: =IF(OR(J11="",L11=""),"", IF(AND(J11="Very High",L11="Excellent"),"Low", IF(AND(J11="Very High",L11="Good"),"Medium", IF(AND(J11="Very High",L11="Fair"),"High", IF(AND(J11="Very High",L11="Poor"),"Very High", IF(AND(J11="Very High",L11="Unsatisfactory"),"Very High", IF(AND(J11="High",L11="Excellent"),"Very Low", IF(AND(J11="High",L11="Good"),"Low", IF(AND(J11="High",L11="Fair"),"Medium", IF(AND(J11="High",L11="Poor"),"High", IF(AND(J11="High",L11="Unsatisfactory"),"High", IF(AND(J11="Medium",L11="Excellent"),"Very Low", IF(AND(J11="Medium",L11="Good"),"Very Low", IF(AND(J11="Medium",L11="Fair"),"Low", IF(AND(J11="Medium",L11="Poor"),"Medium", IF(AND(J11="Medium",L11="Unsatisfactory"),"Medium", IF(AND(J11="Low",L11="Excellent"),"Very Low", IF(AND(J11="Low",L11="Good"),"Very Low", IF(AND(J11="Low",L11="Fair"),"Very Low", IF(AND(J11="Low",L11="Poor"),"Low", IF(AND(J11="Low",L11="Unsatisfactory"),"Low", IF(AND(J11="Very Low",L11="Excellent"),"Very Low", IF(AND(J11="Very Low",L11="Good"),"Very Low", IF(AND(J11="Very Low",L11="Fair"),"Very Low", IF(AND(J11="Very Low",L11="Poor"),"Very Low", IF(AND(J11="Very Low",L11="Unsatisfactory"),"Very Low","")))))))))))))))))))))))))) -> Medium | S11: =IF(OR(L11="",R11=""),"",IF(AND(L11="Very High",R11="Excellent"),"Low",IF(AND(L11="Very High",R11="Good"),"Medium",IF(AND(L11="Very High",R11="Fair"),"High",IF(AND(L11="Very High",R11="Poor"),"Very High",IF(AND(L11="Very High",R11="Unsatisfactory"),"Very High",IF(AND(L11="High",R11="Excellent"),"Low",IF(AND(L11="High",R11="Good"),"Low",IF(AND(L11="High",R11="Fair"),"Medium",IF(AND(L11="High",R11="Poor"),"High",IF(AND(L11="High",R11="Unsatisfactory"),"High",IF(AND(L11="Medium",R11="Excellent"),"Low",IF(AND(L11="Medium",R11="Good"),"Low",IF(AND(L11="Medium",R11="Fair"),"Low",IF(AND(L11="Medium",R11="Poor"),"Medium",IF(AND(L11="Medium",R11="Unsatisfactory"),"Medium",IF(AND(L11="Low",R11="Excellent"),"Very Low",IF(AND(L11="Low",R11="Good"),"Low",IF(AND(L11="Low",R11="Fair"),"Low",IF(AND(L11="Low",R11="Poor"),"Low",IF(AND(L11="Low",R11="Unsatisfactory"),"Low",IF(AND(L11="Very Low",R11="Excellent"),"Very Low",IF(AND(L11="Very Low",R11="Good"),"Very Low",IF(AND(L11="Very Low",R11="Fair"),"Very Low",IF(AND(L11="Very Low",R11="Poor"),"Very Low",IF(AND(L11="Very Low",R11="Unsatisfactory"),"Very Low","Low")))))))))))))))))))))))))) | T11: Reportt every suspocous transaction to SAFIU within 10 days
A12: AFC-005 | B12: People | C12: Dealing with Prohibited clients | D12: Anti Money Laundering | E12: Risk of dealing with a customer that are registered in the sanction lists, lead to financial loss, reputational impact and legal prosecution. | F12: Almost certain | G12: Major | H12: =IF(F12='Risk Methedology Matrix'!B$26,5,IF(F12='Risk Methedology Matrix'!B$27,4,IF(F12='Risk Methedology Matrix'!B$28,3,IF(F12='Risk Methedology Matrix'!B$29,2,IF(F12='Risk Methedology Matrix'!B$30,1,0))))) -> 5 | I12: =IF(G12='Risk Methedology Matrix'!G$25,5,IF(G12='Risk Methedology Matrix'!F$25,4,IF(G12='Risk Methedology Matrix'!E$25,3,IF(G12='Risk Methedology Matrix'!D$25,2,IF(G12='Risk Methedology Matrix'!C$25,1,0))))) -> 4 | J12: =IF(OR(F12="",G12=""),"",IF(H12*I12>=20,"Very High",IF(AND(H12*I12<20,H12*I12>=11),"High",IF(AND(H12*I12<11,H12*I12>=6),"Medium",IF(AND(H12*I12<6,H12*I12>=3),"Low",IF(AND(H12*I12<3,H12*I12>=1),"Very Low","")))))) -> Very High | K12: FOCAL is used as a preventive control to verify customer names against the relevant sanctions lists before establishing a business relationship Evidence of the verification is documented and retained The customer portfolio is also subject to periodic screening to detect newly listed or prohibited customers and prevent further dealings with them. | L12: Good | M12: =IF(OR(J12="",L12=""),"", IF(AND(J12="Very High",L12="Excellent"),"Low", IF(AND(J12="Very High",L12="Good"),"Medium", IF(AND(J12="Very High",L12="Fair"),"High", IF(AND(J12="Very High",L12="Poor"),"Very High", IF(AND(J12="Very High",L12="Unsatisfactory"),"Very High", IF(AND(J12="High",L12="Excellent"),"Very Low", IF(AND(J12="High",L12="Good"),"Low", IF(AND(J12="High",L12="Fair"),"Medium", IF(AND(J12="High",L12="Poor"),"High", IF(AND(J12="High",L12="Unsatisfactory"),"High", IF(AND(J12="Medium",L12="Excellent"),"Very Low", IF(AND(J12="Medium",L12="Good"),"Very Low", IF(AND(J12="Medium",L12="Fair"),"Low", IF(AND(J12="Medium",L12="Poor"),"Medium", IF(AND(J12="Medium",L12="Unsatisfactory"),"Medium", IF(AND(J12="Low",L12="Excellent"),"Very Low", IF(AND(J12="Low",L12="Good"),"Very Low", IF(AND(J12="Low",L12="Fair"),"Very Low", IF(AND(J12="Low",L12="Poor"),"Low", IF(AND(J12="Low",L12="Unsatisfactory"),"Low", IF(AND(J12="Very Low",L12="Excellent"),"Very Low", IF(AND(J12="Very Low",L12="Good"),"Very Low", IF(AND(J12="Very Low",L12="Fair"),"Very Low", IF(AND(J12="Very Low",L12="Poor"),"Very Low", IF(AND(J12="Very Low",L12="Unsatisfactory"),"Very Low","")))))))))))))))))))))))))) -> Medium | S12: =IF(OR(L12="",R12=""),"",IF(AND(L12="Very High",R12="Excellent"),"Low",IF(AND(L12="Very High",R12="Good"),"Medium",IF(AND(L12="Very High",R12="Fair"),"High",IF(AND(L12="Very High",R12="Poor"),"Very High",IF(AND(L12="Very High",R12="Unsatisfactory"),"Very High",IF(AND(L12="High",R12="Excellent"),"Low",IF(AND(L12="High",R12="Good"),"Low",IF(AND(L12="High",R12="Fair"),"Medium",IF(AND(L12="High",R12="Poor"),"High",IF(AND(L12="High",R12="Unsatisfactory"),"High",IF(AND(L12="Medium",R12="Excellent"),"Low",IF(AND(L12="Medium",R12="Good"),"Low",IF(AND(L12="Medium",R12="Fair"),"Low",IF(AND(L12="Medium",R12="Poor"),"Medium",IF(AND(L12="Medium",R12="Unsatisfactory"),"Medium",IF(AND(L12="Low",R12="Excellent"),"Very Low",IF(AND(L12="Low",R12="Good"),"Low",IF(AND(L12="Low",R12="Fair"),"Low",IF(AND(L12="Low",R12="Poor"),"Low",IF(AND(L12="Low",R12="Unsatisfactory"),"Low",IF(AND(L12="Very Low",R12="Excellent"),"Very Low",IF(AND(L12="Very Low",R12="Good"),"Very Low",IF(AND(L12="Very Low",R12="Fair"),"Very Low",IF(AND(L12="Very Low",R12="Poor"),"Very Low",IF(AND(L12="Very Low",R12="Unsatisfactory"),"Very Low","Low")))))))))))))))))))))))))) | T12: (Check with Operation about procedures to deal with Prohibited clients)
A13: AFC-006 | B13: People | C13: POS terminal | D13: Anti Money Laundering | E13: Risk of an individual performing suspicious transactions on their POS terminal, to lead to fraudulent transaction legal prosecution. | F13: Possible | G13: Critical | H13: =IF(F13='Risk Methedology Matrix'!B$26,5,IF(F13='Risk Methedology Matrix'!B$27,4,IF(F13='Risk Methedology Matrix'!B$28,3,IF(F13='Risk Methedology Matrix'!B$29,2,IF(F13='Risk Methedology Matrix'!B$30,1,0))))) -> 3 | I13: =IF(G13='Risk Methedology Matrix'!G$25,5,IF(G13='Risk Methedology Matrix'!F$25,4,IF(G13='Risk Methedology Matrix'!E$25,3,IF(G13='Risk Methedology Matrix'!D$25,2,IF(G13='Risk Methedology Matrix'!C$25,1,0))))) -> 5 | J13: =IF(OR(F13="",G13=""),"",IF(H13*I13>=20,"Very High",IF(AND(H13*I13<20,H13*I13>=11),"High",IF(AND(H13*I13<11,H13*I13>=6),"Medium",IF(AND(H13*I13<6,H13*I13>=3),"Low",IF(AND(H13*I13<3,H13*I13>=1),"Very Low","")))))) -> High | K13: We have different rules against which we monitor customer transctions via Focal APIs and raise a flag immediately if that happens 1-Establish a formal SOP for investigating, documenting, and escalating POS-related alerts 2-Develop and implement risk-based AML monitoring scenarios and alert thresholds tailored to merchant profiles, transaction behavior, and risk levels 3-Ensure all alerts are reviewed, investigated, and documented with clear audit trails 4-Enforce escalation procedures for suspicious activities, including submission to Compliance for further review and action 5-Integrate POS monitoring with the central transaction monitoring system to ensure consistency and full visibility 6-Conduct targeted training for relevant staff on AML monitoring scenarios and red flags related to POS transactions. 7-Perform periodic tuning and effectiveness testing of monitoring scenarios to enhance detection accuracy and reduce false positives | L13: Fair | M13: =IF(OR(J13="",L13=""),"", IF(AND(J13="Very High",L13="Excellent"),"Low", IF(AND(J13="Very High",L13="Good"),"Medium", IF(AND(J13="Very High",L13="Fair"),"High", IF(AND(J13="Very High",L13="Poor"),"Very High", IF(AND(J13="Very High",L13="Unsatisfactory"),"Very High", IF(AND(J13="High",L13="Excellent"),"Very Low", IF(AND(J13="High",L13="Good"),"Low", IF(AND(J13="High",L13="Fair"),"Medium", IF(AND(J13="High",L13="Poor"),"High", IF(AND(J13="High",L13="Unsatisfactory"),"High", IF(AND(J13="Medium",L13="Excellent"),"Very Low", IF(AND(J13="Medium",L13="Good"),"Very Low", IF(AND(J13="Medium",L13="Fair"),"Low", IF(AND(J13="Medium",L13="Poor"),"Medium", IF(AND(J13="Medium",L13="Unsatisfactory"),"Medium", IF(AND(J13="Low",L13="Excellent"),"Very Low", IF(AND(J13="Low",L13="Good"),"Very Low", IF(AND(J13="Low",L13="Fair"),"Very Low", IF(AND(J13="Low",L13="Poor"),"Low", IF(AND(J13="Low",L13="Unsatisfactory"),"Low", IF(AND(J13="Very Low",L13="Excellent"),"Very Low", IF(AND(J13="Very Low",L13="Good"),"Very Low", IF(AND(J13="Very Low",L13="Fair"),"Very Low", IF(AND(J13="Very Low",L13="Poor"),"Very Low", IF(AND(J13="Very Low",L13="Unsatisfactory"),"Very Low","")))))))))))))))))))))))))) -> Medium | S13: =IF(OR(L13="",R13=""),"",IF(AND(L13="Very High",R13="Excellent"),"Low",IF(AND(L13="Very High",R13="Good"),"Medium",IF(AND(L13="Very High",R13="Fair"),"High",IF(AND(L13="Very High",R13="Poor"),"Very High",IF(AND(L13="Very High",R13="Unsatisfactory"),"Very High",IF(AND(L13="High",R13="Excellent"),"Low",IF(AND(L13="High",R13="Good"),"Low",IF(AND(L13="High",R13="Fair"),"Medium",IF(AND(L13="High",R13="Poor"),"High",IF(AND(L13="High",R13="Unsatisfactory"),"High",IF(AND(L13="Medium",R13="Excellent"),"Low",IF(AND(L13="Medium",R13="Good"),"Low",IF(AND(L13="Medium",R13="Fair"),"Low",IF(AND(L13="Medium",R13="Poor"),"Medium",IF(AND(L13="Medium",R13="Unsatisfactory"),"Medium",IF(AND(L13="Low",R13="Excellent"),"Very Low",IF(AND(L13="Low",R13="Good"),"Low",IF(AND(L13="Low",R13="Fair"),"Low",IF(AND(L13="Low",R13="Poor"),"Low",IF(AND(L13="Low",R13="Unsatisfactory"),"Low",IF(AND(L13="Very Low",R13="Excellent"),"Very Low",IF(AND(L13="Very Low",R13="Good"),"Very Low",IF(AND(L13="Very Low",R13="Fair"),"Very Low",IF(AND(L13="Very Low",R13="Poor"),"Very Low",IF(AND(L13="Very Low",R13="Unsatisfactory"),"Very Low","Low")))))))))))))))))))))))))) | T13: (Action plan to reduce the alerts on focal + time line + controls)
A14: AFC-007 | B14: System | C14: Lack of E-KYC | D14: Anti Money Laundering | E14: Risk of E-KYC, lead to operation insufficiency and fraudulent transaction | F14: Possible | G14: Moderate | H14: =IF(F14='Risk Methedology Matrix'!B$26,5,IF(F14='Risk Methedology Matrix'!B$27,4,IF(F14='Risk Methedology Matrix'!B$28,3,IF(F14='Risk Methedology Matrix'!B$29,2,IF(F14='Risk Methedology Matrix'!B$30,1,0))))) -> 3 | I14: =IF(G14='Risk Methedology Matrix'!G$25,5,IF(G14='Risk Methedology Matrix'!F$25,4,IF(G14='Risk Methedology Matrix'!E$25,3,IF(G14='Risk Methedology Matrix'!D$25,2,IF(G14='Risk Methedology Matrix'!C$25,1,0))))) -> 3 | J14: High | K14: 1- E-KYC implementation during the onboarding process using Elm and Wathiq Services 2- Customer information update incase of E-KYC is due for renewal | L14: Poor | M14: =IF(OR(J14="",L14=""),"", IF(AND(J14="Very High",L14="Excellent"),"Low", IF(AND(J14="Very High",L14="Good"),"Medium", IF(AND(J14="Very High",L14="Fair"),"High", IF(AND(J14="Very High",L14="Poor"),"Very High", IF(AND(J14="Very High",L14="Unsatisfactory"),"Very High", IF(AND(J14="High",L14="Excellent"),"Very Low", IF(AND(J14="High",L14="Good"),"Low", IF(AND(J14="High",L14="Fair"),"Medium", IF(AND(J14="High",L14="Poor"),"High", IF(AND(J14="High",L14="Unsatisfactory"),"High", IF(AND(J14="Medium",L14="Excellent"),"Very Low", IF(AND(J14="Medium",L14="Good"),"Very Low", IF(AND(J14="Medium",L14="Fair"),"Low", IF(AND(J14="Medium",L14="Poor"),"Medium", IF(AND(J14="Medium",L14="Unsatisfactory"),"Medium", IF(AND(J14="Low",L14="Excellent"),"Very Low", IF(AND(J14="Low",L14="Good"),"Very Low", IF(AND(J14="Low",L14="Fair"),"Very Low", IF(AND(J14="Low",L14="Poor"),"Low", IF(AND(J14="Low",L14="Unsatisfactory"),"Low", IF(AND(J14="Very Low",L14="Excellent"),"Very Low", IF(AND(J14="Very Low",L14="Good"),"Very Low", IF(AND(J14="Very Low",L14="Fair"),"Very Low", IF(AND(J14="Very Low",L14="Poor"),"Very Low", IF(AND(J14="Very Low",L14="Unsatisfactory"),"Very Low","")))))))))))))))))))))))))) -> High | O14: Strengthen E-KYC controls by ensuring mandatory non-bypassable identity verification during onboarding using approved third-party sources with defined renewal and data update mechanisms | P14: 1-Implement mandatory E-KYC verification for all customers during onboarding using approved platforms (e.g., Elm, Wathiq) 2-Ensure E-KYC is a non-bypassable step prior to account activation 3-Define E-KYC validity periods and implement automated renewal processes 4-Ensure timely update of customer information upon E-KYC expiry or trigger events 5-Monitor E-KYC completion rates and address any system or integration gaps | Q14: Q4 timeline | S14: =IF(OR(L14="",R14=""),"",IF(AND(L14="Very High",R14="Excellent"),"Low",IF(AND(L14="Very High",R14="Good"),"Medium",IF(AND(L14="Very High",R14="Fair"),"High",IF(AND(L14="Very High",R14="Poor"),"Very High",IF(AND(L14="Very High",R14="Unsatisfactory"),"Very High",IF(AND(L14="High",R14="Excellent"),"Low",IF(AND(L14="High",R14="Good"),"Low",IF(AND(L14="High",R14="Fair"),"Medium",IF(AND(L14="High",R14="Poor"),"High",IF(AND(L14="High",R14="Unsatisfactory"),"High",IF(AND(L14="Medium",R14="Excellent"),"Low",IF(AND(L14="Medium",R14="Good"),"Low",IF(AND(L14="Medium",R14="Fair"),"Low",IF(AND(L14="Medium",R14="Poor"),"Medium",IF(AND(L14="Medium",R14="Unsatisfactory"),"Medium",IF(AND(L14="Low",R14="Excellent"),"Very Low",IF(AND(L14="Low",R14="Good"),"Low",IF(AND(L14="Low",R14="Fair"),"Low",IF(AND(L14="Low",R14="Poor"),"Low",IF(AND(L14="Low",R14="Unsatisfactory"),"Low",IF(AND(L14="Very Low",R14="Excellent"),"Very Low",IF(AND(L14="Very Low",R14="Good"),"Very Low",IF(AND(L14="Very Low",R14="Fair"),"Very Low",IF(AND(L14="Very Low",R14="Poor"),"Very Low",IF(AND(L14="Very Low",R14="Unsatisfactory"),"Very Low","Low")))))))))))))))))))))))))) | T14: (Ask operation team for the effectiveness of controls) (effectiveness of the control is the evidence
A15: AFC-008 | B15: Process | C15: Due Deligence | D15: Anti Money Laundering | E15: Ineffective customer due diligence (CDD) and enhanced due diligence (EDD) processes. | F15: Unlikely | G15: Moderate | H15: =IF(F15='Risk Methedology Matrix'!B$26,5,IF(F15='Risk Methedology Matrix'!B$27,4,IF(F15='Risk Methedology Matrix'!B$28,3,IF(F15='Risk Methedology Matrix'!B$29,2,IF(F15='Risk Methedology Matrix'!B$30,1,0))))) -> 2 | I15: =IF(G15='Risk Methedology Matrix'!G$25,5,IF(G15='Risk Methedology Matrix'!F$25,4,IF(G15='Risk Methedology Matrix'!E$25,3,IF(G15='Risk Methedology Matrix'!D$25,2,IF(G15='Risk Methedology Matrix'!C$25,1,0))))) -> 3 | J15: High | K15: Establish and enforce CDD/EDD procedures, including risk scoring and PEP checks during onboarding and periodic reviews. 1-Enhance existing CDD and EDD procedures to ensure consistent application across all customers 2-Strengthen customer risk scoring methodology to support accurate risk classification 3-Ensure effective identification and handling of PEP customers during onboarding and periodic reviews 4-Standardize documentation and verification requirements for CDD/EDD processes 5-Ensure periodic review of customer information based on defined review cycles | L15: Good | M15: =IF(OR(J15="",L15=""),"", IF(AND(J15="Very High",L15="Excellent"),"Low", IF(AND(J15="Very High",L15="Good"),"Medium", IF(AND(J15="Very High",L15="Fair"),"High", IF(AND(J15="Very High",L15="Poor"),"Very High", IF(AND(J15="Very High",L15="Unsatisfactory"),"Very High", IF(AND(J15="High",L15="Excellent"),"Very Low", IF(AND(J15="High",L15="Good"),"Low", IF(AND(J15="High",L15="Fair"),"Medium", IF(AND(J15="High",L15="Poor"),"High", IF(AND(J15="High",L15="Unsatisfactory"),"High", IF(AND(J15="Medium",L15="Excellent"),"Very Low", IF(AND(J15="Medium",L15="Good"),"Very Low", IF(AND(J15="Medium",L15="Fair"),"Low", IF(AND(J15="Medium",L15="Poor"),"Medium", IF(AND(J15="Medium",L15="Unsatisfactory"),"Medium", IF(AND(J15="Low",L15="Excellent"),"Very Low", IF(AND(J15="Low",L15="Good"),"Very Low", IF(AND(J15="Low",L15="Fair"),"Very Low", IF(AND(J15="Low",L15="Poor"),"Low", IF(AND(J15="Low",L15="Unsatisfactory"),"Low", IF(AND(J15="Very Low",L15="Excellent"),"Very Low", IF(AND(J15="Very Low",L15="Good"),"Very Low", IF(AND(J15="Very Low",L15="Fair"),"Very Low", IF(AND(J15="Very Low",L15="Poor"),"Very Low", IF(AND(J15="Very Low",L15="Unsatisfactory"),"Very Low","")))))))))))))))))))))))))) -> Low | S15: =IF(OR(L15="",R15=""),"",IF(AND(L15="Very High",R15="Excellent"),"Low",IF(AND(L15="Very High",R15="Good"),"Medium",IF(AND(L15="Very High",R15="Fair"),"High",IF(AND(L15="Very High",R15="Poor"),"Very High",IF(AND(L15="Very High",R15="Unsatisfactory"),"Very High",IF(AND(L15="High",R15="Excellent"),"Low",IF(AND(L15="High",R15="Good"),"Low",IF(AND(L15="High",R15="Fair"),"Medium",IF(AND(L15="High",R15="Poor"),"High",IF(AND(L15="High",R15="Unsatisfactory"),"High",IF(AND(L15="Medium",R15="Excellent"),"Low",IF(AND(L15="Medium",R15="Good"),"Low",IF(AND(L15="Medium",R15="Fair"),"Low",IF(AND(L15="Medium",R15="Poor"),"Medium",IF(AND(L15="Medium",R15="Unsatisfactory"),"Medium",IF(AND(L15="Low",R15="Excellent"),"Very Low",IF(AND(L15="Low",R15="Good"),"Low",IF(AND(L15="Low",R15="Fair"),"Low",IF(AND(L15="Low",R15="Poor"),"Low",IF(AND(L15="Low",R15="Unsatisfactory"),"Low",IF(AND(L15="Very Low",R15="Excellent"),"Very Low",IF(AND(L15="Very Low",R15="Good"),"Very Low",IF(AND(L15="Very Low",R15="Fair"),"Very Low",IF(AND(L15="Very Low",R15="Poor"),"Very Low",IF(AND(L15="Very Low",R15="Unsatisfactory"),"Very Low","Low")))))))))))))))))))))))))) | T15: (Ask operation team for the effectiveness of controls) (effectiveness of the control is the evidence
A16: AFC-009 | B16: Process | C16: Risk of Onboarding | D16: Anti Money Laundering | E16: Risk of Onboarding fictitious or anonymous customers | F16: Likely | G16: Critical | H16: =IF(F16='Risk Methedology Matrix'!B$26,5,IF(F16='Risk Methedology Matrix'!B$27,4,IF(F16='Risk Methedology Matrix'!B$28,3,IF(F16='Risk Methedology Matrix'!B$29,2,IF(F16='Risk Methedology Matrix'!B$30,1,0))))) -> 4 | I16: =IF(G16='Risk Methedology Matrix'!G$25,5,IF(G16='Risk Methedology Matrix'!F$25,4,IF(G16='Risk Methedology Matrix'!E$25,3,IF(G16='Risk Methedology Matrix'!D$25,2,IF(G16='Risk Methedology Matrix'!C$25,1,0))))) -> 5 | J16: =IF(OR(F16="",G16=""),"",IF(H16*I16>=20,"Very High",IF(AND(H16*I16<20,H16*I16>=11),"High",IF(AND(H16*I16<11,H16*I16>=6),"Medium",IF(AND(H16*I16<6,H16*I16>=3),"Low",IF(AND(H16*I16<3,H16*I16>=1),"Very Low","")))))) -> Very High | K16: Prohibit anonymous or numerically coded accounts and verify customer identities through official documentation. '1-Developed and implemented mandatory CDD/EDD procedures for all customers. 2-Implement risk-based customer classification using automated scoring models 3-Integrate sanctions and PEP screening within onboarding using a reliable vendor 4-Enforce Compliance review and approval for high-risk and EDD cases 5-Implement system controls to block onboarding until all checks and approvals are completed 6-Ensure all customer data is obtained and verified through reliable independent sources | L16: Good | M16: =IF(OR(J16="",L16=""),"", IF(AND(J16="Very High",L16="Excellent"),"Low", IF(AND(J16="Very High",L16="Good"),"Medium", IF(AND(J16="Very High",L16="Fair"),"High", IF(AND(J16="Very High",L16="Poor"),"Very High", IF(AND(J16="Very High",L16="Unsatisfactory"),"Very High", IF(AND(J16="High",L16="Excellent"),"Very Low", IF(AND(J16="High",L16="Good"),"Low", IF(AND(J16="High",L16="Fair"),"Medium", IF(AND(J16="High",L16="Poor"),"High", IF(AND(J16="High",L16="Unsatisfactory"),"High", IF(AND(J16="Medium",L16="Excellent"),"Very Low", IF(AND(J16="Medium",L16="Good"),"Very Low", IF(AND(J16="Medium",L16="Fair"),"Low", IF(AND(J16="Medium",L16="Poor"),"Medium", IF(AND(J16="Medium",L16="Unsatisfactory"),"Medium", IF(AND(J16="Low",L16="Excellent"),"Very Low", IF(AND(J16="Low",L16="Good"),"Very Low", IF(AND(J16="Low",L16="Fair"),"Very Low", IF(AND(J16="Low",L16="Poor"),"Low", IF(AND(J16="Low",L16="Unsatisfactory"),"Low", IF(AND(J16="Very Low",L16="Excellent"),"Very Low", IF(AND(J16="Very Low",L16="Good"),"Very Low", IF(AND(J16="Very Low",L16="Fair"),"Very Low", IF(AND(J16="Very Low",L16="Poor"),"Very Low", IF(AND(J16="Very Low",L16="Unsatisfactory"),"Very Low","")))))))))))))))))))))))))) -> Medium | S16: =IF(OR(L16="",R16=""),"",IF(AND(L16="Very High",R16="Excellent"),"Low",IF(AND(L16="Very High",R16="Good"),"Medium",IF(AND(L16="Very High",R16="Fair"),"High",IF(AND(L16="Very High",R16="Poor"),"Very High",IF(AND(L16="Very High",R16="Unsatisfactory"),"Very High",IF(AND(L16="High",R16="Excellent"),"Low",IF(AND(L16="High",R16="Good"),"Low",IF(AND(L16="High",R16="Fair"),"Medium",IF(AND(L16="High",R16="Poor"),"High",IF(AND(L16="High",R16="Unsatisfactory"),"High",IF(AND(L16="Medium",R16="Excellent"),"Low",IF(AND(L16="Medium",R16="Good"),"Low",IF(AND(L16="Medium",R16="Fair"),"Low",IF(AND(L16="Medium",R16="Poor"),"Medium",IF(AND(L16="Medium",R16="Unsatisfactory"),"Medium",IF(AND(L16="Low",R16="Excellent"),"Very Low",IF(AND(L16="Low",R16="Good"),"Low",IF(AND(L16="Low",R16="Fair"),"Low",IF(AND(L16="Low",R16="Poor"),"Low",IF(AND(L16="Low",R16="Unsatisfactory"),"Low",IF(AND(L16="Very Low",R16="Excellent"),"Very Low",IF(AND(L16="Very Low",R16="Good"),"Very Low",IF(AND(L16="Very Low",R16="Fair"),"Very Low",IF(AND(L16="Very Low",R16="Poor"),"Very Low",IF(AND(L16="Very Low",R16="Unsatisfactory"),"Very Low","Low")))))))))))))))))))))))))) | T16: (Ask operation team for the effectiveness of controls) (effectiveness of the control is the evidence
A17: AFC-010 | B17: Process | C17: Policies and Procedures | D17: Anti Money Laundering | E17: Risk of the absence of a reviewed, updated, and comprehensive Policies and Procedures Manual covering all departmental functions, potentially resulting in operational inefficiencies, role ambiguity, and misalignment of responsibilities | F17: Unlikely | G17: Moderate | H17: =IF(F17='Risk Methedology Matrix'!B$26,5,IF(F17='Risk Methedology Matrix'!B$27,4,IF(F17='Risk Methedology Matrix'!B$28,3,IF(F17='Risk Methedology Matrix'!B$29,2,IF(F17='Risk Methedology Matrix'!B$30,1,0))))) -> 2 | I17: =IF(G17='Risk Methedology Matrix'!G$25,5,IF(G17='Risk Methedology Matrix'!F$25,4,IF(G17='Risk Methedology Matrix'!E$25,3,IF(G17='Risk Methedology Matrix'!D$25,2,IF(G17='Risk Methedology Matrix'!C$25,1,0))))) -> 3 | J17: =IF(OR(F17="",G17=""),"",IF(H17*I17>=20,"Very High",IF(AND(H17*I17<20,H17*I17>=11),"High",IF(AND(H17*I17<11,H17*I17>=6),"Medium",IF(AND(H17*I17<6,H17*I17>=3),"Low",IF(AND(H17*I17<3,H17*I17>=1),"Very Low","")))))) -> Medium | K17: Perform annual reviews of the AML framework, involving independent audits to assess effectiveness. | L17: Fair | M17: =IF(OR(J17="",L17=""),"", IF(AND(J17="Very High",L17="Excellent"),"Low", IF(AND(J17="Very High",L17="Good"),"Medium", IF(AND(J17="Very High",L17="Fair"),"High", IF(AND(J17="Very High",L17="Poor"),"Very High", IF(AND(J17="Very High",L17="Unsatisfactory"),"Very High", IF(AND(J17="High",L17="Excellent"),"Very Low", IF(AND(J17="High",L17="Good"),"Low", IF(AND(J17="High",L17="Fair"),"Medium", IF(AND(J17="High",L17="Poor"),"High", IF(AND(J17="High",L17="Unsatisfactory"),"High", IF(AND(J17="Medium",L17="Excellent"),"Very Low", IF(AND(J17="Medium",L17="Good"),"Very Low", IF(AND(J17="Medium",L17="Fair"),"Low", IF(AND(J17="Medium",L17="Poor"),"Medium", IF(AND(J17="Medium",L17="Unsatisfactory"),"Medium", IF(AND(J17="Low",L17="Excellent"),"Very Low", IF(AND(J17="Low",L17="Good"),"Very Low", IF(AND(J17="Low",L17="Fair"),"Very Low", IF(AND(J17="Low",L17="Poor"),"Low", IF(AND(J17="Low",L17="Unsatisfactory"),"Low", IF(AND(J17="Very Low",L17="Excellent"),"Very Low", IF(AND(J17="Very Low",L17="Good"),"Very Low", IF(AND(J17="Very Low",L17="Fair"),"Very Low", IF(AND(J17="Very Low",L17="Poor"),"Very Low", IF(AND(J17="Very Low",L17="Unsatisfactory"),"Very Low","")))))))))))))))))))))))))) -> Low | S17: =IF(OR(L17="",R17=""),"",IF(AND(L17="Very High",R17="Excellent"),"Low",IF(AND(L17="Very High",R17="Good"),"Medium",IF(AND(L17="Very High",R17="Fair"),"High",IF(AND(L17="Very High",R17="Poor"),"Very High",IF(AND(L17="Very High",R17="Unsatisfactory"),"Very High",IF(AND(L17="High",R17="Excellent"),"Low",IF(AND(L17="High",R17="Good"),"Low",IF(AND(L17="High",R17="Fair"),"Medium",IF(AND(L17="High",R17="Poor"),"High",IF(AND(L17="High",R17="Unsatisfactory"),"High",IF(AND(L17="Medium",R17="Excellent"),"Low",IF(AND(L17="Medium",R17="Good"),"Low",IF(AND(L17="Medium",R17="Fair"),"Low",IF(AND(L17="Medium",R17="Poor"),"Medium",IF(AND(L17="Medium",R17="Unsatisfactory"),"Medium",IF(AND(L17="Low",R17="Excellent"),"Very Low",IF(AND(L17="Low",R17="Good"),"Low",IF(AND(L17="Low",R17="Fair"),"Low",IF(AND(L17="Low",R17="Poor"),"Low",IF(AND(L17="Low",R17="Unsatisfactory"),"Low",IF(AND(L17="Very Low",R17="Excellent"),"Very Low",IF(AND(L17="Very Low",R17="Good"),"Very Low",IF(AND(L17="Very Low",R17="Fair"),"Very Low",IF(AND(L17="Very Low",R17="Poor"),"Very Low",IF(AND(L17="Very Low",R17="Unsatisfactory"),"Very Low","Low")))))))))))))))))))))))))) | T17: Update the Policies for AML And fraud within 4 months
A18: AFC-011 | B18: Process | C18: Annual Strategy | D18: Anti Money Laundering | E18: Failure to develop a comprehensive strategy and roadmap for the department. | F18: Likely | G18: Minor | H18: =IF(F18='Risk Methedology Matrix'!B$26,5,IF(F18='Risk Methedology Matrix'!B$27,4,IF(F18='Risk Methedology Matrix'!B$28,3,IF(F18='Risk Methedology Matrix'!B$29,2,IF(F18='Risk Methedology Matrix'!B$30,1,0))))) -> 4 | I18: =IF(G18='Risk Methedology Matrix'!G$25,5,IF(G18='Risk Methedology Matrix'!F$25,4,IF(G18='Risk Methedology Matrix'!E$25,3,IF(G18='Risk Methedology Matrix'!D$25,2,IF(G18='Risk Methedology Matrix'!C$25,1,0))))) -> 2 | J18: =IF(OR(F18="",G18=""),"",IF(H18*I18>=20,"Very High",IF(AND(H18*I18<20,H18*I18>=11),"High",IF(AND(H18*I18<11,H18*I18>=6),"Medium",IF(AND(H18*I18<6,H18*I18>=3),"Low",IF(AND(H18*I18<3,H18*I18>=1),"Very Low","")))))) -> Medium | K18: Established and maintain a structured annual AML and Risk strategy aligned with business objectives regulatory requirements and risk appetite with clear governance and performance tracking. 1-Developed an annual AML/Risk strategy aligned with business growth and regulatory expectations 2-Define clear objectives, initiatives, and KPIs for all AML activities 3-Obtain Senior Management and Board approval for the strategy 4-Monitor progress against KPIs on a periodic basis (e.g., monthly/quarterly). 5-Escalate any delays or deviations and implement corrective actions in a timely manner 6-Conduct periodic reviews and update the strategy as needed based on emerging risks | L18: Good | M18: =IF(OR(J18="",L18=""),"", IF(AND(J18="Very High",L18="Excellent"),"Low", IF(AND(J18="Very High",L18="Good"),"Medium", IF(AND(J18="Very High",L18="Fair"),"High", IF(AND(J18="Very High",L18="Poor"),"Very High", IF(AND(J18="Very High",L18="Unsatisfactory"),"Very High", IF(AND(J18="High",L18="Excellent"),"Very Low", IF(AND(J18="High",L18="Good"),"Low", IF(AND(J18="High",L18="Fair"),"Medium", IF(AND(J18="High",L18="Poor"),"High", IF(AND(J18="High",L18="Unsatisfactory"),"High", IF(AND(J18="Medium",L18="Excellent"),"Very Low", IF(AND(J18="Medium",L18="Good"),"Very Low", IF(AND(J18="Medium",L18="Fair"),"Low", IF(AND(J18="Medium",L18="Poor"),"Medium", IF(AND(J18="Medium",L18="Unsatisfactory"),"Medium", IF(AND(J18="Low",L18="Excellent"),"Very Low", IF(AND(J18="Low",L18="Good"),"Very Low", IF(AND(J18="Low",L18="Fair"),"Very Low", IF(AND(J18="Low",L18="Poor"),"Low", IF(AND(J18="Low",L18="Unsatisfactory"),"Low", IF(AND(J18="Very Low",L18="Excellent"),"Very Low", IF(AND(J18="Very Low",L18="Good"),"Very Low", IF(AND(J18="Very Low",L18="Fair"),"Very Low", IF(AND(J18="Very Low",L18="Poor"),"Very Low", IF(AND(J18="Very Low",L18="Unsatisfactory"),"Very Low","")))))))))))))))))))))))))) -> Very Low | S18: =IF(OR(L18="",R18=""),"",IF(AND(L18="Very High",R18="Excellent"),"Low",IF(AND(L18="Very High",R18="Good"),"Medium",IF(AND(L18="Very High",R18="Fair"),"High",IF(AND(L18="Very High",R18="Poor"),"Very High",IF(AND(L18="Very High",R18="Unsatisfactory"),"Very High",IF(AND(L18="High",R18="Excellent"),"Low",IF(AND(L18="High",R18="Good"),"Low",IF(AND(L18="High",R18="Fair"),"Medium",IF(AND(L18="High",R18="Poor"),"High",IF(AND(L18="High",R18="Unsatisfactory"),"High",IF(AND(L18="Medium",R18="Excellent"),"Low",IF(AND(L18="Medium",R18="Good"),"Low",IF(AND(L18="Medium",R18="Fair"),"Low",IF(AND(L18="Medium",R18="Poor"),"Medium",IF(AND(L18="Medium",R18="Unsatisfactory"),"Medium",IF(AND(L18="Low",R18="Excellent"),"Very Low",IF(AND(L18="Low",R18="Good"),"Low",IF(AND(L18="Low",R18="Fair"),"Low",IF(AND(L18="Low",R18="Poor"),"Low",IF(AND(L18="Low",R18="Unsatisfactory"),"Low",IF(AND(L18="Very Low",R18="Excellent"),"Very Low",IF(AND(L18="Very Low",R18="Good"),"Very Low",IF(AND(L18="Very Low",R18="Fair"),"Very Low",IF(AND(L18="Very Low",R18="Poor"),"Very Low",IF(AND(L18="Very Low",R18="Unsatisfactory"),"Very Low","Low")))))))))))))))))))))))))) | T18: (Activate compliance committee ask Khalid alzaini)
A19: AFC-012 | B19: Process | C19: Human Resourcing | D19: Anti Money Laundering | E19: Failure to accurately identify, budget, and communicate the department’s human resource requirements to the Human Resources function may result in misalignment between manpower planning and recruitment activities. This could lead to staffing shortages or surpluses, disrupting departmental operations and impacting service delivery | F19: Likely | G19: Minor | H19: =IF(F19='Risk Methedology Matrix'!B$26,5,IF(F19='Risk Methedology Matrix'!B$27,4,IF(F19='Risk Methedology Matrix'!B$28,3,IF(F19='Risk Methedology Matrix'!B$29,2,IF(F19='Risk Methedology Matrix'!B$30,1,0))))) -> 4 | I19: =IF(G19='Risk Methedology Matrix'!G$25,5,IF(G19='Risk Methedology Matrix'!F$25,4,IF(G19='Risk Methedology Matrix'!E$25,3,IF(G19='Risk Methedology Matrix'!D$25,2,IF(G19='Risk Methedology Matrix'!C$25,1,0))))) -> 2 | J19: =IF(OR(F19="",G19=""),"",IF(H19*I19>=20,"Very High",IF(AND(H19*I19<20,H19*I19>=11),"High",IF(AND(H19*I19<11,H19*I19>=6),"Medium",IF(AND(H19*I19<6,H19*I19>=3),"Low",IF(AND(H19*I19<3,H19*I19>=1),"Very Low","")))))) -> Medium | K19: Established a formal workforce planning process that involves collaboration between department heads and the HR function. | L19: Poor | M19: =IF(OR(J19="",L19=""),"", IF(AND(J19="Very High",L19="Excellent"),"Low", IF(AND(J19="Very High",L19="Good"),"Medium", IF(AND(J19="Very High",L19="Fair"),"High", IF(AND(J19="Very High",L19="Poor"),"Very High", IF(AND(J19="Very High",L19="Unsatisfactory"),"Very High", IF(AND(J19="High",L19="Excellent"),"Very Low", IF(AND(J19="High",L19="Good"),"Low", IF(AND(J19="High",L19="Fair"),"Medium", IF(AND(J19="High",L19="Poor"),"High", IF(AND(J19="High",L19="Unsatisfactory"),"High", IF(AND(J19="Medium",L19="Excellent"),"Very Low", IF(AND(J19="Medium",L19="Good"),"Very Low", IF(AND(J19="Medium",L19="Fair"),"Low", IF(AND(J19="Medium",L19="Poor"),"Medium", IF(AND(J19="Medium",L19="Unsatisfactory"),"Medium", IF(AND(J19="Low",L19="Excellent"),"Very Low", IF(AND(J19="Low",L19="Good"),"Very Low", IF(AND(J19="Low",L19="Fair"),"Very Low", IF(AND(J19="Low",L19="Poor"),"Low", IF(AND(J19="Low",L19="Unsatisfactory"),"Low", IF(AND(J19="Very Low",L19="Excellent"),"Very Low", IF(AND(J19="Very Low",L19="Good"),"Very Low", IF(AND(J19="Very Low",L19="Fair"),"Very Low", IF(AND(J19="Very Low",L19="Poor"),"Very Low", IF(AND(J19="Very Low",L19="Unsatisfactory"),"Very Low","")))))))))))))))))))))))))) -> Medium | O19: Recruitment will be conducted based on approved and available positions to meet operational requirements | P19: Fill approved vacant positions based on business requirements | Q19: Q4 timeline | S19: =IF(OR(L19="",R19=""),"",IF(AND(L19="Very High",R19="Excellent"),"Low",IF(AND(L19="Very High",R19="Good"),"Medium",IF(AND(L19="Very High",R19="Fair"),"High",IF(AND(L19="Very High",R19="Poor"),"Very High",IF(AND(L19="Very High",R19="Unsatisfactory"),"Very High",IF(AND(L19="High",R19="Excellent"),"Low",IF(AND(L19="High",R19="Good"),"Low",IF(AND(L19="High",R19="Fair"),"Medium",IF(AND(L19="High",R19="Poor"),"High",IF(AND(L19="High",R19="Unsatisfactory"),"High",IF(AND(L19="Medium",R19="Excellent"),"Low",IF(AND(L19="Medium",R19="Good"),"Low",IF(AND(L19="Medium",R19="Fair"),"Low",IF(AND(L19="Medium",R19="Poor"),"Medium",IF(AND(L19="Medium",R19="Unsatisfactory"),"Medium",IF(AND(L19="Low",R19="Excellent"),"Very Low",IF(AND(L19="Low",R19="Good"),"Low",IF(AND(L19="Low",R19="Fair"),"Low",IF(AND(L19="Low",R19="Poor"),"Low",IF(AND(L19="Low",R19="Unsatisfactory"),"Low",IF(AND(L19="Very Low",R19="Excellent"),"Very Low",IF(AND(L19="Very Low",R19="Good"),"Very Low",IF(AND(L19="Very Low",R19="Fair"),"Very Low",IF(AND(L19="Very Low",R19="Poor"),"Very Low",IF(AND(L19="Very Low",R19="Unsatisfactory"),"Very Low","Low")))))))))))))))))))))))))) | T19: (allocate Budget For AML and fraud ) -Khalid alzaini or Finance department
A20: AFC-013 | B20: Process | C20: Training & Sufficient Nnumbers | D20: Anti Money Laundering | E20: Failure to identify and effectively communicate the training needs and requirements of department employees to the Human Resources function may result in inadequate skill development, reduced employee performance, and hindered overall departmental growth and effectiveness. | F20: Possible | G20: Minor | H20: =IF(F20='Risk Methedology Matrix'!B$26,5,IF(F20='Risk Methedology Matrix'!B$27,4,IF(F20='Risk Methedology Matrix'!B$28,3,IF(F20='Risk Methedology Matrix'!B$29,2,IF(F20='Risk Methedology Matrix'!B$30,1,0))))) -> 3 | I20: =IF(G20='Risk Methedology Matrix'!G$25,5,IF(G20='Risk Methedology Matrix'!F$25,4,IF(G20='Risk Methedology Matrix'!E$25,3,IF(G20='Risk Methedology Matrix'!D$25,2,IF(G20='Risk Methedology Matrix'!C$25,1,0))))) -> 2 | J20: =IF(OR(F20="",G20=""),"",IF(H20*I20>=20,"Very High",IF(AND(H20*I20<20,H20*I20>=11),"High",IF(AND(H20*I20<11,H20*I20>=6),"Medium",IF(AND(H20*I20<6,H20*I20>=3),"Low",IF(AND(H20*I20<3,H20*I20>=1),"Very Low","")))))) -> Medium | K20: Conduct mandatory AFC awareness training for all employees, including tailored programs for high-risk roles. | L20: Good | M20: =IF(OR(J20="",L20=""),"", IF(AND(J20="Very High",L20="Excellent"),"Low", IF(AND(J20="Very High",L20="Good"),"Medium", IF(AND(J20="Very High",L20="Fair"),"High", IF(AND(J20="Very High",L20="Poor"),"Very High", IF(AND(J20="Very High",L20="Unsatisfactory"),"Very High", IF(AND(J20="High",L20="Excellent"),"Very Low", IF(AND(J20="High",L20="Good"),"Low", IF(AND(J20="High",L20="Fair"),"Medium", IF(AND(J20="High",L20="Poor"),"High", IF(AND(J20="High",L20="Unsatisfactory"),"High", IF(AND(J20="Medium",L20="Excellent"),"Very Low", IF(AND(J20="Medium",L20="Good"),"Very Low", IF(AND(J20="Medium",L20="Fair"),"Low", IF(AND(J20="Medium",L20="Poor"),"Medium", IF(AND(J20="Medium",L20="Unsatisfactory"),"Medium", IF(AND(J20="Low",L20="Excellent"),"Very Low", IF(AND(J20="Low",L20="Good"),"Very Low", IF(AND(J20="Low",L20="Fair"),"Very Low", IF(AND(J20="Low",L20="Poor"),"Low", IF(AND(J20="Low",L20="Unsatisfactory"),"Low", IF(AND(J20="Very Low",L20="Excellent"),"Very Low", IF(AND(J20="Very Low",L20="Good"),"Very Low", IF(AND(J20="Very Low",L20="Fair"),"Very Low", IF(AND(J20="Very Low",L20="Poor"),"Very Low", IF(AND(J20="Very Low",L20="Unsatisfactory"),"Very Low","")))))))))))))))))))))))))) -> Very Low | S20: =IF(OR(L20="",R20=""),"",IF(AND(L20="Very High",R20="Excellent"),"Low",IF(AND(L20="Very High",R20="Good"),"Medium",IF(AND(L20="Very High",R20="Fair"),"High",IF(AND(L20="Very High",R20="Poor"),"Very High",IF(AND(L20="Very High",R20="Unsatisfactory"),"Very High",IF(AND(L20="High",R20="Excellent"),"Low",IF(AND(L20="High",R20="Good"),"Low",IF(AND(L20="High",R20="Fair"),"Medium",IF(AND(L20="High",R20="Poor"),"High",IF(AND(L20="High",R20="Unsatisfactory"),"High",IF(AND(L20="Medium",R20="Excellent"),"Low",IF(AND(L20="Medium",R20="Good"),"Low",IF(AND(L20="Medium",R20="Fair"),"Low",IF(AND(L20="Medium",R20="Poor"),"Medium",IF(AND(L20="Medium",R20="Unsatisfactory"),"Medium",IF(AND(L20="Low",R20="Excellent"),"Very Low",IF(AND(L20="Low",R20="Good"),"Low",IF(AND(L20="Low",R20="Fair"),"Low",IF(AND(L20="Low",R20="Poor"),"Low",IF(AND(L20="Low",R20="Unsatisfactory"),"Low",IF(AND(L20="Very Low",R20="Excellent"),"Very Low",IF(AND(L20="Very Low",R20="Good"),"Very Low",IF(AND(L20="Very Low",R20="Fair"),"Very Low",IF(AND(L20="Very Low",R20="Poor"),"Very Low",IF(AND(L20="Very Low",R20="Unsatisfactory"),"Very Low","Low")))))))))))))))))))))))))) | T20: (Share AFC training with HR and conduct training and awareness sessions)
